<sdf version='1.4'>
  <world name='default'>
    <light name='sun' type='directional'>
      <cast_shadows>1</cast_shadows>
      <pose>0 0 10 0 -0 0</pose>
      <diffuse>0.8 0.8 0.8 1</diffuse>
      <specular>0.2 0.2 0.2 1</specular>
      <attenuation>
        <range>1000</range>
        <constant>0.9</constant>
        <linear>0.01</linear>
        <quadratic>0.001</quadratic>
      </attenuation>
      <direction>-0.5 0.1 -0.9</direction>
    </light>
    <model name='ground_plane'>
      <static>1</static>
      <link name='link'>
        <collision name='collision'>
          <geometry>
            <plane>
              <normal>0 0 1</normal>
              <size>100 100</size>
            </plane>
          </geometry>
          <surface>
            <friction>
              <ode>
                <mu>100</mu>
                <mu2>50</mu2>
              </ode>
            </friction>
            <bounce/>
            <contact>
              <ode/>
            </contact>
          </surface>
          <max_contacts>10</max_contacts>
        </collision>
        <visual name='visual'>
          <cast_shadows>0</cast_shadows>
          <geometry>
            <plane>
              <normal>0 0 1</normal>
              <size>100 100</size>
            </plane>
          </geometry>
          <material>
            <script>
              <uri>file://media/materials/scripts/gazebo.material</uri>
              <name>Gazebo/Grey</name>
            </script>
          </material>
        </visual>
        <velocity_decay>
          <linear>0</linear>
          <angular>0</angular>
        </velocity_decay>
        <self_collide>0</self_collide>
        <kinematic>0</kinematic>
        <gravity>1</gravity>
      </link>
    </model>
    <physics type='ode'>
      <max_step_size>0.001</max_step_size>
      <real_time_factor>1</real_time_factor>
      <real_time_update_rate>1000</real_time_update_rate>
      <gravity>0 0 -9.8</gravity>
    </physics>
    <scene>
      <ambient>0.4 0.4 0.4 1</ambient>
      <background>0.7 0.7 0.7 1</background>
      <shadows>1</shadows>
    </scene>
    <spherical_coordinates>
      <surface_model>EARTH_WGS84</surface_model>
      <latitude_deg>0</latitude_deg>
      <longitude_deg>0</longitude_deg>
      <elevation>0</elevation>
      <heading_deg>0</heading_deg>
    </spherical_coordinates>
    <model name='UPlat'>
      <link name='Wall_0'>
        <pose>2.5 0 0 0 -0 0</pose>
        <visual name='Wall_0_Visual_0'>
          <pose>-2.35094 0 0.5 0 -0 0</pose>
          <geometry>
            <box>
              <size>0.398124 0.1 1</size>
            </box>
          </geometry>
          <material>
            <script>
              <uri>file://media/materials/scripts/gazebo.material</uri>
              <name>Gazebo/Grey</name>
            </script>
          </material>
        </visual>
        <collision name='Wall_0_Collision_0'>
          <geometry>
            <box>
              <size>0.398124 0.1 1</size>
            </box>
          </geometry>
          <pose>-2.35094 0 0.5 0 -0 0</pose>
          <max_contacts>10</max_contacts>
          <surface>
            <bounce/>
            <friction>
              <ode/>
            </friction>
            <contact>
              <ode/>
            </contact>
          </surface>
        </collision>
        <visual name='Wall_0_Visual_1'>
          <pose>0.699062 0 0.5 0 -0 0</pose>
          <geometry>
            <box>
              <size>3.70188 0.1 1</size>
            </box>
          </geometry>
          <material>
            <script>
              <uri>file://media/materials/scripts/gazebo.material</uri>
              <name>Gazebo/Grey</name>
            </script>
          </material>
        </visual>
        <collision name='Wall_0_Collision_1'>
          <geometry>
            <box>
              <size>3.70188 0.1 1</size>
            </box>
          </geometry>
          <pose>0.699062 0 0.5 0 -0 0</pose>
          <max_contacts>10</max_contacts>
          <surface>
            <bounce/>
            <friction>
              <ode/>
            </friction>
            <contact>
              <ode/>
            </contact>
          </surface>
        </collision>
        <velocity_decay>
          <linear>0</linear>
          <angular>0</angular>
        </velocity_decay>
        <self_collide>0</self_collide>
        <kinematic>0</kinematic>
        <gravity>1</gravity>
      </link>
      <link name='Wall_10'>
        <collision name='Wall_10_Collision'>
          <geometry>
            <box>
              <size>3.1 0.1 1</size>
            </box>
          </geometry>
          <pose>0 0 0.5 0 -0 0</pose>
          <max_contacts>10</max_contacts>
          <surface>
            <bounce/>
            <friction>
              <ode/>
            </friction>
            <contact>
              <ode/>
            </contact>
          </surface>
        </collision>
        <visual name='Wall_10_Visual'>
          <pose>0 0 0.5 0 -0 0</pose>
          <geometry>
            <box>
              <size>3.1 0.1 1</size>
            </box>
          </geometry>
          <material>
            <script>
              <uri>file://media/materials/scripts/gazebo.material</uri>
              <name>Gazebo/Grey</name>
            </script>
          </material>
        </visual>
        <velocity_decay>
          <linear>0</linear>
          <angular>0</angular>
        </velocity_decay>
        <pose>4 2.5 0 0 -0 1.5708</pose>
        <self_collide>0</self_collide>
        <kinematic>0</kinematic>
        <gravity>1</gravity>
      </link>
      <link name='Wall_12'>
        <collision name='Wall_12_Collision'>
          <geometry>
            <box>
              <size>2.1 0.1 1</size>
            </box>
          </geometry>
          <pose>0 0 0.5 0 -0 0</pose>
          <max_contacts>10</max_contacts>
          <surface>
            <bounce/>
            <friction>
              <ode/>
            </friction>
            <contact>
              <ode/>
            </contact>
          </surface>
        </collision>
        <visual name='Wall_12_Visual'>
          <pose>0 0 0.5 0 -0 0</pose>
          <geometry>
            <box>
              <size>2.1 0.1 1</size>
            </box>
          </geometry>
          <material>
            <script>
              <uri>file://media/materials/scripts/gazebo.material</uri>
              <name>Gazebo/Grey</name>
            </script>
          </material>
        </visual>
        <velocity_decay>
          <linear>0</linear>
          <angular>0</angular>
        </velocity_decay>
        <pose>2 4 0 0 -0 3.14159</pose>
        <self_collide>0</self_collide>
        <kinematic>0</kinematic>
        <gravity>1</gravity>
      </link>
      <link name='Wall_14'>
        <collision name='Wall_14_Collision'>
          <geometry>
            <box>
              <size>1.1 0.1 1</size>
            </box>
          </geometry>
          <pose>0 0 0.5 0 -0 0</pose>
          <max_contacts>10</max_contacts>
          <surface>
            <bounce/>
            <friction>
              <ode/>
            </friction>
            <contact>
              <ode/>
            </contact>
          </surface>
        </collision>
        <visual name='Wall_14_Visual'>
          <pose>0 0 0.5 0 -0 0</pose>
          <geometry>
            <box>
              <size>1.1 0.1 1</size>
            </box>
          </geometry>
          <material>
            <script>
              <uri>file://media/materials/scripts/gazebo.material</uri>
              <name>Gazebo/Grey</name>
            </script>
          </material>
        </visual>
        <velocity_decay>
          <linear>0</linear>
          <angular>0</angular>
        </velocity_decay>
        <pose>1 3.5 0 0 0 -1.5708</pose>
        <self_collide>0</self_collide>
        <kinematic>0</kinematic>
        <gravity>1</gravity>
      </link>
      <link name='Wall_16'>
        <collision name='Wall_16_Collision'>
          <geometry>
            <box>
              <size>1.1 0.1 1</size>
            </box>
          </geometry>
          <pose>0 0 0.5 0 -0 0</pose>
          <max_contacts>10</max_contacts>
          <surface>
            <bounce/>
            <friction>
              <ode/>
            </friction>
            <contact>
              <ode/>
            </contact>
          </surface>
        </collision>
        <visual name='Wall_16_Visual'>
          <pose>0 0 0.5 0 -0 0</pose>
          <geometry>
            <box>
              <size>1.1 0.1 1</size>
            </box>
          </geometry>
          <material>
            <script>
              <uri>file://media/materials/scripts/gazebo.material</uri>
              <name>Gazebo/Grey</name>
            </script>
          </material>
        </visual>
        <velocity_decay>
          <linear>0</linear>
          <angular>0</angular>
        </velocity_decay>
        <pose>1.5 2 0 0 -0 0</pose>
        <self_collide>0</self_collide>
        <kinematic>0</kinematic>
        <gravity>1</gravity>
      </link>
      <link name='Wall_2'>
        <collision name='Wall_2_Collision'>
          <geometry>
            <box>
              <size>5.1 0.1 1</size>
            </box>
          </geometry>
          <pose>0 0 0.5 0 -0 0</pose>
          <max_contacts>10</max_contacts>
          <surface>
            <bounce/>
            <friction>
              <ode/>
            </friction>
            <contact>
              <ode/>
            </contact>
          </surface>
        </collision>
        <visual name='Wall_2_Visual'>
          <pose>0 0 0.5 0 -0 0</pose>
          <geometry>
            <box>
              <size>5.1 0.1 1</size>
            </box>
          </geometry>
          <material>
            <script>
              <uri>file://media/materials/scripts/gazebo.material</uri>
              <name>Gazebo/Grey</name>
            </script>
          </material>
        </visual>
        <velocity_decay>
          <linear>0</linear>
          <angular>0</angular>
        </velocity_decay>
        <pose>5 2.5 0 0 -0 1.5708</pose>
        <self_collide>0</self_collide>
        <kinematic>0</kinematic>
        <gravity>1</gravity>
      </link>
      <link name='Wall_4'>
        <collision name='Wall_4_Collision'>
          <geometry>
            <box>
              <size>5.1 0.1 1</size>
            </box>
          </geometry>
          <pose>0 0 0.5 0 -0 0</pose>
          <max_contacts>10</max_contacts>
          <surface>
            <bounce/>
            <friction>
              <ode/>
            </friction>
            <contact>
              <ode/>
            </contact>
          </surface>
        </collision>
        <visual name='Wall_4_Visual'>
          <pose>0 0 0.5 0 -0 0</pose>
          <geometry>
            <box>
              <size>5.1 0.1 1</size>
            </box>
          </geometry>
          <material>
            <script>
              <uri>file://media/materials/scripts/gazebo.material</uri>
              <name>Gazebo/Grey</name>
            </script>
          </material>
        </visual>
        <velocity_decay>
          <linear>0</linear>
          <angular>0</angular>
        </velocity_decay>
        <pose>2.5 5 0 0 -0 3.14159</pose>
        <self_collide>0</self_collide>
        <kinematic>0</kinematic>
        <gravity>1</gravity>
      </link>
      <link name='Wall_6'>
        <collision name='Wall_6_Collision'>
          <geometry>
            <box>
              <size>5.1 0.1 1</size>
            </box>
          </geometry>
          <pose>0 0 0.5 0 -0 0</pose>
          <max_contacts>10</max_contacts>
          <surface>
            <bounce/>
            <friction>
              <ode/>
            </friction>
            <contact>
              <ode/>
            </contact>
          </surface>
        </collision>
        <visual name='Wall_6_Visual'>
          <pose>0 0 0.5 0 -0 0</pose>
          <geometry>
            <box>
              <size>5.1 0.1 1</size>
            </box>
          </geometry>
          <material>
            <script>
              <uri>file://media/materials/scripts/gazebo.material</uri>
              <name>Gazebo/Grey</name>
            </script>
          </material>
        </visual>
        <velocity_decay>
          <linear>0</linear>
          <angular>0</angular>
        </velocity_decay>
        <pose>0 2.5 0 0 0 -1.5708</pose>
        <self_collide>0</self_collide>
        <kinematic>0</kinematic>
        <gravity>1</gravity>
      </link>
      <link name='Wall_8'>
        <collision name='Wall_8_Collision'>
          <geometry>
            <box>
              <size>3.1 0.1 1</size>
            </box>
          </geometry>
          <pose>0 0 0.5 0 -0 0</pose>
          <max_contacts>10</max_contacts>
          <surface>
            <bounce/>
            <friction>
              <ode/>
            </friction>
            <contact>
              <ode/>
            </contact>
          </surface>
        </collision>
        <visual name='Wall_8_Visual'>
          <pose>0 0 0.5 0 -0 0</pose>
          <geometry>
            <box>
              <size>3.1 0.1 1</size>
            </box>
          </geometry>
          <material>
            <script>
              <uri>file://media/materials/scripts/gazebo.material</uri>
              <name>Gazebo/Grey</name>
            </script>
          </material>
        </visual>
        <velocity_decay>
          <linear>0</linear>
          <angular>0</angular>
        </velocity_decay>
        <pose>2.5 1 0 0 -0 0</pose>
        <self_collide>0</self_collide>
        <kinematic>0</kinematic>
        <gravity>1</gravity>
      </link>
      <static>1</static>
    </model>
    <model name='box'>
      <pose>2.5 2.5 10 -2.65355e-06 1.57079 1.57079</pose>
      <link name='cam_link'>
        <collision name='cam_collision'>
          <geometry>
            <box>
              <size>0.15 0.15 0.15</size>
            </box>
          </geometry>
          <max_contacts>10</max_contacts>
          <surface>
            <bounce/>
            <friction>
              <ode/>
            </friction>
            <contact>
              <ode/>
            </contact>
          </surface>
        </collision>
        <visual name='cam_visual'>
          <geometry>
            <box>
              <size>0.15 0.15 0.15</size>
            </box>
          </geometry>
        </visual>
        <gravity>0</gravity>
        <sensor name='my_sensor' type='camera'>
          <camera name='__default__'>
            <horizontal_fov>1.047</horizontal_fov>
            <image>
              <width>1600</width>
              <height>900</height>
            </image>
            <clip>
              <near>0.2</near>
              <far>100</far>
            </clip>
          </camera>
          <plugin name='CameraPublisher' filename='libgazebo_ros_camera.so'/>
          <always_on>1</always_on>
          <update_rate>30</update_rate>
          <visualize>1</visualize>
        </sensor>
        <velocity_decay>
          <linear>0</linear>
          <angular>0</angular>
        </velocity_decay>
        <self_collide>0</self_collide>
        <inertial>
          <inertia>
            <ixx>1</ixx>
            <ixy>0</ixy>
            <ixz>0</ixz>
            <iyy>1</iyy>
            <iyz>0</iyz>
            <izz>1</izz>
          </inertia>
          <mass>1</mass>
        </inertial>
        <kinematic>0</kinematic>
      </link>
      <static>0</static>
    </model>
    <model name='first_2015_trash_can'>
      <link name='link'>
        <inertial>
          <pose>0 0 0.3683 0 -0 0</pose>
          <mass>4.83076</mass>
          <inertia>
            <ixx>0.281534</ixx>
            <ixy>0</ixy>
            <ixz>0</ixz>
            <iyy>0.281534</iyy>
            <iyz>0</iyz>
            <izz>0.126223</izz>
          </inertia>
        </inertial>
        <visual name='visual'>
          <geometry>
            <mesh>
              <uri>model://first_2015_trash_can/meshes/trash_can.dae</uri>
            </mesh>
          </geometry>
        </visual>
        <collision name='collision'>
          <geometry>
            <mesh>
              <uri>model://first_2015_trash_can/meshes/trash_can.dae</uri>
            </mesh>
          </geometry>
          <max_contacts>10</max_contacts>
          <surface>
            <bounce/>
            <friction>
              <ode/>
            </friction>
            <contact>
              <ode/>
            </contact>
          </surface>
        </collision>
        <velocity_decay>
          <linear>0</linear>
          <angular>0</angular>
        </velocity_decay>
        <self_collide>0</self_collide>
        <kinematic>0</kinematic>
        <gravity>1</gravity>
      </link>
      <pose>4.59463 4.58969 0 0 -0 0</pose>
      <static>0</static>
    </model>
    <state world_name='default'>
      <sim_time>2261 690000000</sim_time>
      <real_time>152 449372497</real_time>
      <wall_time>1526722513 28195128</wall_time>
      <model name='UPlat'>
        <pose>0 0 0 0 -0 0</pose>
        <link name='Wall_0'>
          <pose>2.5 0 0 0 -0 0</pose>
          <velocity>0 0 0 0 -0 0</velocity>
          <acceleration>0 0 0 0 -0 0</acceleration>
          <wrench>0 0 0 0 -0 0</wrench>
        </link>
        <link name='Wall_10'>
          <pose>4 2.5 0 0 -0 1.5708</pose>
          <velocity>0 0 0 0 -0 0</velocity>
          <acceleration>0 0 0 0 -0 0</acceleration>
          <wrench>0 0 0 0 -0 0</wrench>
        </link>
        <link name='Wall_12'>
          <pose>2 4 0 0 -0 3.14159</pose>
          <velocity>0 0 0 0 -0 0</velocity>
          <acceleration>0 0 0 0 -0 0</acceleration>
          <wrench>0 0 0 0 -0 0</wrench>
        </link>
        <link name='Wall_14'>
          <pose>1 3.5 0 0 0 -1.5708</pose>
          <velocity>0 0 0 0 -0 0</velocity>
          <acceleration>0 0 0 0 -0 0</acceleration>
          <wrench>0 0 0 0 -0 0</wrench>
        </link>
        <link name='Wall_16'>
          <pose>1.5 2 0 0 -0 0</pose>
          <velocity>0 0 0 0 -0 0</velocity>
          <acceleration>0 0 0 0 -0 0</acceleration>
          <wrench>0 0 0 0 -0 0</wrench>
        </link>
        <link name='Wall_2'>
          <pose>5 2.5 0 0 -0 1.5708</pose>
          <velocity>0 0 0 0 -0 0</velocity>
          <acceleration>0 0 0 0 -0 0</acceleration>
          <wrench>0 0 0 0 -0 0</wrench>
        </link>
        <link name='Wall_4'>
          <pose>2.5 5 0 0 -0 3.14159</pose>
          <velocity>0 0 0 0 -0 0</velocity>
          <acceleration>0 0 0 0 -0 0</acceleration>
          <wrench>0 0 0 0 -0 0</wrench>
        </link>
        <link name='Wall_6'>
          <pose>0 2.5 0 0 0 -1.5708</pose>
          <velocity>0 0 0 0 -0 0</velocity>
          <acceleration>0 0 0 0 -0 0</acceleration>
          <wrench>0 0 0 0 -0 0</wrench>
        </link>
        <link name='Wall_8'>
          <pose>2.5 1 0 0 -0 0</pose>
          <velocity>0 0 0 0 -0 0</velocity>
          <acceleration>0 0 0 0 -0 0</acceleration>
          <wrench>0 0 0 0 -0 0</wrench>
        </link>
      </model>
      <model name='armadillo'>
        <pose>1.03346 0.515697 -8.6e-05 -1.2e-05 0.000287 1.75291</pose>
        <link name='base_footprint'>
          <pose>1.03346 0.515697 -8.6e-05 -1.2e-05 0.000287 1.75291</pose>
          <velocity>-1.3e-05 0.000282 0.000607 0.002109 -0.000544 4.7e-05</velocity>
          <acceleration>0 0 0 0 -0 0</acceleration>
          <wrench>0 0 0 0 -0 0</wrench>
        </link>
        <link name='head_pan_link'>
          <pose>1.0447 0.454579 0.963714 -0.0001 0.000266 1.43895</pose>
          <velocity>-0.000488 -0.001943 -0.018884 0.001197 -0.000474 -0.002517</velocity>
          <acceleration>0 0 0 0 -0 0</acceleration>
          <wrench>0 0 0 0 -0 0</wrench>
        </link>
        <link name='head_tilt_link'>
          <pose>1.0447 0.454594 1.01471 -0.000181 0.988535 1.4388</pose>
          <velocity>-0.00048 -0.002011 -0.017257 0.001961 -0.000379 0.007148</velocity>
          <acceleration>0 0 0 0 -0 0</acceleration>
          <wrench>0 0 0 0 -0 0</wrench>
        </link>
        <link name='left_finger_link'>
          <pose>0.883083 0.647667 1.09478 0.208039 -0.338173 0.580737</pose>
          <velocity>0.00642 -0.000362 -0.014809 -0.030747 0.016669 -0.018944</velocity>
          <acceleration>0 0 0 0 -0 0</acceleration>
          <wrench>0 0 0 0 -0 0</wrench>
        </link>
        <link name='left_wheel_link'>
          <pose>0.877079 0.486927 0.094912 -1.6e-05 0.31204 1.75291</pose>
          <velocity>-5.8e-05 -2.5e-05 0.000481 0.00028 -0.000594 0.000647</velocity>
          <acceleration>0 0 0 0 -0 0</acceleration>
          <wrench>0 0 0 0 -0 0</wrench>
        </link>
        <link name='right_finger_link'>
          <pose>0.906633 0.612937 1.09298 -0.116948 -0.338176 0.580741</pose>
          <velocity>0.005528 -0.000998 -0.01432 -0.032294 0.018912 -0.019178</velocity>
          <acceleration>0 0 0 0 -0 0</acceleration>
          <wrench>0 0 0 0 -0 0</wrench>
        </link>
        <link name='right_wheel_link'>
          <pose>1.18982 0.544519 0.094916 -8e-06 0.298046 1.7529</pose>
          <velocity>-6e-05 -2.7e-05 0.000765 0.000228 -0.000636 -0.000854</velocity>
          <acceleration>0 0 0 0 -0 0</acceleration>
          <wrench>0 0 0 0 -0 0</wrench>
        </link>
        <link name='rotation1_link'>
          <pose>1.01784 0.600467 0.402389 0.000179 0.000304 2.40191</pose>
          <velocity>-0.000313 -0.000689 -0.017934 0.012458 0.000156 -0.000611</velocity>
          <acceleration>0 0 0 0 -0 0</acceleration>
          <wrench>0 0 0 0 -0 0</wrench>
        </link>
        <link name='rotation2_link'>
          <pose>0.941929 0.661718 0.905921 -0.040631 -0.000102 0.831937</pose>
          <velocity>0.002651 -0.007472 -0.016748 -0.029857 0.025033 -0.004996</velocity>
          <acceleration>0 0 0 0 -0 0</acceleration>
          <wrench>0 0 0 0 -0 0</wrench>
        </link>
        <link name='shoulder1_link'>
          <pose>1.01784 0.600483 0.441388 0.000179 0.347583 2.40198</pose>
          <velocity>-0.000418 -0.001437 -0.017899 0.013398 0.003652 -0.005089</velocity>
          <acceleration>0 0 0 0 -0 0</acceleration>
          <wrench>0 0 0 0 -0 0</wrench>
        </link>
        <link name='shoulder2_link'>
          <pose>0.9306 0.680139 0.679382 0.000127 -0.744622 2.40184</pose>
          <velocity>0.00054 -0.005147 -0.016617 0.006785 0.012304 -0.005569</velocity>
          <acceleration>0 0 0 0 -0 0</acceleration>
          <wrench>0 0 0 0 -0 0</wrench>
        </link>
        <link name='shoulder3_link'>
          <pose>0.945383 0.658565 0.938637 -0.04305 -0.33852 0.846274</pose>
          <velocity>0.00353 -0.006206 -0.016544 -0.033328 0.021738 -0.021014</velocity>
          <acceleration>0 0 0 0 -0 0</acceleration>
          <wrench>0 0 0 0 -0 0</wrench>
        </link>
        <link name='torso_link'>
          <pose>1.05883 0.377882 0.588745 -1.2e-05 0.000287 1.75291</pose>
          <velocity>-0.000313 -0.000975 -0.018699 0.002216 -0.000538 6.1e-05</velocity>
          <acceleration>0 0 0 0 -0 0</acceleration>
          <wrench>0 0 0 0 -0 0</wrench>
        </link>
        <link name='wrist_link'>
          <pose>0.907022 0.640913 1.04841 0.045546 -0.33818 0.58074</pose>
          <velocity>0.005264 -0.002344 -0.015152 -0.03087 0.019219 -0.019824</velocity>
          <acceleration>0 0 0 0 -0 0</acceleration>
          <wrench>0 0 0 0 -0 0</wrench>
        </link>
      </model>
      <model name='box'>
        <pose>2.5 2.5 10 -3.00003e-06 1.57079 1.57079</pose>
        <link name='cam_link'>
          <pose>2.5 2.5 10 -3.00003e-06 1.57079 1.57079</pose>
          <velocity>0 0 0 0 -0 0</velocity>
          <acceleration>0 0 0 0 -0 0</acceleration>
          <wrench>0 0 0 0 -0 0</wrench>
        </link>
      </model>
      <model name='first_2015_trash_can'>
        <pose>3.59057 1.41199 -2e-06 3e-06 7e-06 -0.024949</pose>
        <link name='link'>
          <pose>3.59057 1.41199 -2e-06 3e-06 7e-06 -0.024949</pose>
          <velocity>0 0 0 0 -0 0</velocity>
          <acceleration>0 0 0 0 -0 0</acceleration>
          <wrench>0 0 0 0 -0 0</wrench>
        </link>
      </model>
      <model name='ground_plane'>
        <pose>0 0 0 0 -0 0</pose>
        <link name='link'>
          <pose>0 0 0 0 -0 0</pose>
          <velocity>0 0 0 0 -0 0</velocity>
          <acceleration>0 0 0 0 -0 0</acceleration>
          <wrench>0 0 0 0 -0 0</wrench>
        </link>
      </model>
    </state>
    <gui fullscreen='0'>
      <camera name='user_camera'>
        <pose>-1.45231 1.41005 21.6678 0 1.3149 0.021696</pose>
        <view_controller>orbit</view_controller>
      </camera>
    </gui>
    <model name='armadillo'>
      <link name='base_footprint'>
        <pose>0 0 0 0 -0 0</pose>
        <inertial>
          <pose>-0.0571874 0.000107493 0.248778 0 -0 0</pose>
          <mass>30.8162</mass>
          <inertia>
            <ixx>0.618038</ixx>
            <ixy>-8.99269e-05</ixy>
            <ixz>-0.0896425</ixz>
            <iyy>0.590993</iyy>
            <iyz>5.21463e-05</iyz>
            <izz>0.377014</izz>
          </inertia>
        </inertial>
        <collision name='base_footprint_collision_base_link'>
          <pose>0 0 0.095 0 -0 0</pose>
          <geometry>
            <mesh>
              <scale>1 1 1</scale>
              <uri>/home/zeged/catkin_ws/src/robotican/robotican_armadillo/description/meshes/base_link.STL</uri>
            </mesh>
          </geometry>
          <surface>
            <contact>
              <ode/>
            </contact>
            <friction>
              <ode/>
            </friction>
            <bounce/>
          </surface>
          <max_contacts>10</max_contacts>
        </collision>
        <collision name='base_footprint_collision_base_link_1'>
          <pose>-0.3 0 0.0475 0 -0 0</pose>
          <geometry>
            <sphere>
              <radius>0.0475</radius>
            </sphere>
          </geometry>
          <max_contacts>10</max_contacts>
          <surface>
            <bounce/>
            <friction>
              <ode/>
            </friction>
            <contact>
              <ode/>
            </contact>
          </surface>
        </collision>
        <collision name='base_footprint_collision_front_cam_link'>
          <pose>0.21658 0 0.1137 0 -0 0</pose>
          <geometry>
            <mesh>
              <scale>1 1 1</scale>
              <uri>/home/zeged/catkin_ws/src/robotican/robotican_armadillo/description/meshes/front_cam_link.STL</uri>
            </mesh>
          </geometry>
          <surface>
            <contact>
              <ode/>
            </contact>
            <friction>
              <ode/>
            </friction>
            <bounce/>
          </surface>
          <max_contacts>10</max_contacts>
        </collision>
        <collision name='base_footprint_collision_laser_link'>
          <pose>0.18961 0 0.1993 0 -0 0</pose>
          <geometry>
            <mesh>
              <scale>1 1 1</scale>
              <uri>/home/zeged/catkin_ws/src/robotican/robotican_armadillo/description/meshes/laser_link.STL</uri>
            </mesh>
          </geometry>
          <surface>
            <contact>
              <ode/>
            </contact>
            <friction>
              <ode/>
            </friction>
            <bounce/>
          </surface>
          <surface>
            <contact>
              <ode/>
            </contact>
            <friction>
              <ode/>
            </friction>
          </surface>
          <max_contacts>10</max_contacts>
        </collision>
        <collision name='base_footprint_collision_left_urf_link'>
          <pose>-0.038417 0.25288 0.2448 -3.14158 1.57079 -1.57078</pose>
          <geometry>
            <cylinder>
              <length>0.01</length>
              <radius>0.008</radius>
            </cylinder>
          </geometry>
          <surface>
            <contact>
              <ode/>
            </contact>
            <friction>
              <ode/>
            </friction>
            <bounce/>
          </surface>
          <max_contacts>10</max_contacts>
        </collision>
        <collision name='base_footprint_collision_rear_urf_link'>
          <pose>-0.28028 0 0.2448 3.14159 1.57079 2.65359e-06</pose>
          <geometry>
            <cylinder>
              <length>0.01</length>
              <radius>0.008</radius>
            </cylinder>
          </geometry>
          <surface>
            <contact>
              <ode/>
            </contact>
            <friction>
              <ode/>
            </friction>
            <bounce/>
          </surface>
          <max_contacts>10</max_contacts>
        </collision>
        <collision name='base_footprint_collision_right_urf_link'>
          <pose>-0.038417 -0.25288 0.2448 3.14158 1.57079 1.57078</pose>
          <geometry>
            <cylinder>
              <length>0.005</length>
              <radius>0.008</radius>
            </cylinder>
          </geometry>
          <surface>
            <contact>
              <ode/>
            </contact>
            <friction>
              <ode/>
            </friction>
            <bounce/>
          </surface>
          <max_contacts>10</max_contacts>
        </collision>
        <visual name='base_footprint_visual_base_link'>
          <pose>0 0 0.095 0 -0 0</pose>
          <geometry>
            <mesh>
              <scale>1 1 1</scale>
              <uri>/home/zeged/catkin_ws/src/robotican/robotican_armadillo/description/meshes/base_link.STL</uri>
            </mesh>
          </geometry>
          <material>
            <script>
              <name>Gazebo/Grey</name>
              <uri>__default__</uri>
            </script>
          </material>
        </visual>
        <visual name='base_footprint_visual_front_cam_link'>
          <pose>0.21658 0 0.1137 0 -0 0</pose>
          <geometry>
            <mesh>
              <scale>1 1 1</scale>
              <uri>/home/zeged/catkin_ws/src/robotican/robotican_armadillo/description/meshes/front_cam_link.STL</uri>
            </mesh>
          </geometry>
          <material>
            <script>
              <name>Gazebo/Black</name>
              <uri>__default__</uri>
            </script>
          </material>
        </visual>
        <visual name='base_footprint_visual_laser_link'>
          <pose>0.18961 0 0.1993 0 -0 0</pose>
          <geometry>
            <mesh>
              <scale>1 1 1</scale>
              <uri>/home/zeged/catkin_ws/src/robotican/robotican_armadillo/description/meshes/laser_link.STL</uri>
            </mesh>
          </geometry>
          <material>
            <script>
              <name>Gazebo/Black</name>
              <uri>__default__</uri>
            </script>
          </material>
        </visual>
        <visual name='base_footprint_visual_left_urf_link'>
          <pose>-0.038417 0.25288 0.2448 -3.14158 1.57079 -1.57078</pose>
          <geometry>
            <cylinder>
              <length>0.005</length>
              <radius>0.008</radius>
            </cylinder>
          </geometry>
          <material>
            <script>
              <name>Gazebo/Black</name>
              <uri>__default__</uri>
            </script>
          </material>
        </visual>
        <visual name='base_footprint_visual_rear_urf_link'>
          <pose>-0.28028 0 0.2448 3.14159 1.57079 2.65359e-06</pose>
          <geometry>
            <cylinder>
              <length>0.005</length>
              <radius>0.008</radius>
            </cylinder>
          </geometry>
          <material>
            <script>
              <name>Gazebo/Black</name>
              <uri>__default__</uri>
            </script>
          </material>
        </visual>
        <visual name='base_footprint_visual_right_urf_link'>
          <pose>-0.038417 -0.25288 0.2448 3.14158 1.57079 1.57078</pose>
          <geometry>
            <cylinder>
              <length>0.005</length>
              <radius>0.008</radius>
            </cylinder>
          </geometry>
          <material>
            <script>
              <name>Gazebo/Black</name>
              <uri>__default__</uri>
            </script>
          </material>
        </visual>
        <velocity_decay>
          <linear>0</linear>
          <angular>0</angular>
        </velocity_decay>
        <velocity_decay>
          <linear>0</linear>
          <angular>0</angular>
        </velocity_decay>
        <velocity_decay>
          <linear>0</linear>
          <angular>0</angular>
        </velocity_decay>
        <sensor name='head_hokuyo_sensor' type='ray'>
          <visualize>0</visualize>
          <update_rate>10</update_rate>
          <ray>
            <scan>
              <horizontal>
                <samples>667</samples>
                <resolution>1</resolution>
                <min_angle>-1.81</min_angle>
                <max_angle>1.81</max_angle>
              </horizontal>
            </scan>
            <range>
              <min>0.02</min>
              <max>5.6</max>
              <resolution>0.01</resolution>
            </range>
            <noise>
              <type>gaussian</type>
              <mean>0</mean>
              <stddev>0.01</stddev>
            </noise>
          </ray>
          <plugin name='gazebo_ros_head_hokuyo_controller' filename='libgazebo_ros_laser.so'>
            <topicName>scan</topicName>
            <frameName>laser_link</frameName>
            <robotNamespace>/</robotNamespace>
          </plugin>
          <pose>0.18961 0 0.1993 0 -0 0</pose>
        </sensor>
        <velocity_decay>
          <linear>0</linear>
          <angular>0</angular>
        </velocity_decay>
        <velocity_decay>
          <linear>0</linear>
          <angular>0</angular>
        </velocity_decay>
        <velocity_decay>
          <linear>0</linear>
          <angular>0</angular>
        </velocity_decay>
        <gravity>1</gravity>
        <velocity_decay>
          <linear>0</linear>
          <angular>0</angular>
        </velocity_decay>
        <self_collide>0</self_collide>
        <kinematic>0</kinematic>
      </link>
      <link name='left_wheel_link'>
        <pose>0 0.159 0.095 0 -0 0</pose>
        <inertial>
          <pose>5.6549e-06 -0.050799 0.030167 0 -0 0</pose>
          <mass>1.8524</mass>
          <inertia>
            <ixx>0.0069046</ixx>
            <ixy>-3.8717e-08</ixy>
            <ixz>2.0707e-07</ixz>
            <iyy>0.013153</iyy>
            <iyz>-1.0124e-07</iyz>
            <izz>0.0069054</izz>
          </inertia>
        </inertial>
        <collision name='left_wheel_link_collision'>
          <pose>0 0 0 1.5708 -0 0</pose>
          <geometry>
            <cylinder>
              <length>0.05</length>
              <radius>0.095</radius>
            </cylinder>
          </geometry>
          <surface>
            <contact>
              <ode>
                <kp>1e+06</kp>
                <kd>100</kd>
                <max_vel>1</max_vel>
                <min_depth>0</min_depth>
              </ode>
            </contact>
            <friction>
              <ode>
                <mu>1.5</mu>
                <mu2>1.5</mu2>
                <fdir1>1 0 0</fdir1>
              </ode>
            </friction>
            <bounce/>
          </surface>
          <max_contacts>10</max_contacts>
        </collision>
        <visual name='left_wheel_link_visual'>
          <pose>0 0 0 1.5708 -0 0</pose>
          <geometry>
            <cylinder>
              <length>0.05</length>
              <radius>0.095</radius>
            </cylinder>
          </geometry>
        </visual>
        <gravity>1</gravity>
        <velocity_decay>
          <linear>0</linear>
          <angular>0</angular>
        </velocity_decay>
        <self_collide>0</self_collide>
        <kinematic>0</kinematic>
      </link>
      <joint name='left_wheel_joint' type='revolute'>
        <child>left_wheel_link</child>
        <parent>base_footprint</parent>
        <axis>
          <xyz>0 1 0</xyz>
          <limit>
            <lower>-1e+16</lower>
            <upper>1e+16</upper>
          </limit>
          <dynamics/>
        </axis>
      </joint>
      <link name='right_wheel_link'>
        <pose>0 -0.159 0.095 0 -0 0</pose>
        <inertial>
          <pose>-5.6549e-06 0.050799 0.030167 0 -0 0</pose>
          <mass>1.8524</mass>
          <inertia>
            <ixx>0.0069046</ixx>
            <ixy>-3.8717e-08</ixy>
            <ixz>-2.0707e-07</ixz>
            <iyy>0.013153</iyy>
            <iyz>1.0124e-07</iyz>
            <izz>0.0069054</izz>
          </inertia>
        </inertial>
        <collision name='right_wheel_link_collision'>
          <pose>0 0 0 1.5708 -0 0</pose>
          <geometry>
            <cylinder>
              <length>0.05</length>
              <radius>0.095</radius>
            </cylinder>
          </geometry>
          <surface>
            <contact>
              <ode>
                <kp>1e+06</kp>
                <kd>100</kd>
                <max_vel>1</max_vel>
                <min_depth>0</min_depth>
              </ode>
            </contact>
            <friction>
              <ode>
                <mu>1.5</mu>
                <mu2>1.5</mu2>
                <fdir1>1 0 0</fdir1>
              </ode>
            </friction>
            <bounce/>
          </surface>
          <max_contacts>10</max_contacts>
        </collision>
        <visual name='right_wheel_link_visual'>
          <pose>0 0 0 1.5708 -0 0</pose>
          <geometry>
            <cylinder>
              <length>0.05</length>
              <radius>0.095</radius>
            </cylinder>
          </geometry>
        </visual>
        <gravity>1</gravity>
        <velocity_decay>
          <linear>0</linear>
          <angular>0</angular>
        </velocity_decay>
        <self_collide>0</self_collide>
        <kinematic>0</kinematic>
      </link>
      <joint name='right_wheel_joint' type='revolute'>
        <child>right_wheel_link</child>
        <parent>base_footprint</parent>
        <axis>
          <xyz>0 1 0</xyz>
          <limit>
            <lower>-1e+16</lower>
            <upper>1e+16</upper>
          </limit>
          <dynamics/>
        </axis>
      </joint>
      <link name='torso_link'>
        <pose>-0.1403 0 0.58881 0 -0 0</pose>
        <inertial>
          <pose>0.186475 -1.73362e-05 -0.138604 0 -0 0</pose>
          <mass>0.426456</mass>
          <inertia>
            <ixx>0.217447</ixx>
            <ixy>6.46693e-05</ixy>
            <ixz>0.000911942</ixz>
            <iyy>0.191507</iyy>
            <iyz>-7.64182e-05</iyz>
            <izz>0.0790137</izz>
          </inertia>
        </inertial>
        <collision name='torso_link_collision'>
          <pose>0 0 0 0 -0 0</pose>
          <geometry>
            <mesh>
              <scale>1 1 1</scale>
              <uri>/home/zeged/catkin_ws/src/robotican/robotican_armadillo/description/meshes/torso_link.STL</uri>
            </mesh>
          </geometry>
          <max_contacts>10</max_contacts>
          <surface>
            <bounce/>
            <friction>
              <ode/>
            </friction>
            <contact>
              <ode/>
            </contact>
          </surface>
        </collision>
        <collision name='torso_link_collision_arm_link'>
          <pose>0.19338 0 -0.25204 0 -0 0</pose>
          <geometry>
            <mesh>
              <scale>1 1 1</scale>
              <uri>/home/zeged/catkin_ws/src/robotican/robotican_armadillo/description/meshes/arm_link.STL</uri>
            </mesh>
          </geometry>
          <surface>
            <contact>
              <ode/>
            </contact>
            <friction>
              <ode/>
            </friction>
            <bounce/>
          </surface>
          <surface>
            <contact>
              <ode/>
            </contact>
            <friction>
              <ode/>
            </friction>
          </surface>
          <surface>
            <contact>
              <ode/>
            </contact>
            <friction>
              <ode/>
            </friction>
          </surface>
          <max_contacts>10</max_contacts>
        </collision>
        <collision name='torso_link_collision_base_arm_link'>
          <pose>0.22638 0 -0.21629 0 -0 0</pose>
          <geometry>
            <mesh>
              <scale>1 1 1</scale>
              <uri>/home/zeged/catkin_ws/src/robotican/robotican_manipulator_h/meshes/base_arm_link.STL</uri>
            </mesh>
          </geometry>
          <surface>
            <contact>
              <ode/>
            </contact>
            <friction>
              <ode/>
            </friction>
            <bounce/>
          </surface>
          <surface>
            <contact>
              <ode/>
            </contact>
            <friction>
              <ode/>
            </friction>
          </surface>
          <surface>
            <contact>
              <ode/>
            </contact>
            <friction>
              <ode/>
            </friction>
          </surface>
          <max_contacts>10</max_contacts>
        </collision>
        <collision name='torso_link_collision_head_link'>
          <pose>0.11288 0 0.26399 0 -0 0</pose>
          <geometry>
            <mesh>
              <scale>1 1 1</scale>
              <uri>/home/zeged/catkin_ws/src/robotican/robotican_armadillo/description/meshes/head_link.STL</uri>
            </mesh>
          </geometry>
          <max_contacts>10</max_contacts>
          <surface>
            <bounce/>
            <friction>
              <ode/>
            </friction>
            <contact>
              <ode/>
            </contact>
          </surface>
        </collision>
        <collision name='torso_link_collision_rear_cam_link'>
          <pose>-0.09712 0 0.13354 0 -0 -3.14159</pose>
          <geometry>
            <mesh>
              <scale>1 1 1</scale>
              <uri>/home/zeged/catkin_ws/src/robotican/robotican_armadillo/description/meshes/rear_cam_link.STL</uri>
            </mesh>
          </geometry>
          <surface>
            <contact>
              <ode/>
            </contact>
            <friction>
              <ode/>
            </friction>
            <bounce/>
          </surface>
          <max_contacts>10</max_contacts>
        </collision>
        <visual name='torso_link_visual'>
          <pose>0 0 0 0 -0 0</pose>
          <geometry>
            <mesh>
              <scale>1 1 1</scale>
              <uri>/home/zeged/catkin_ws/src/robotican/robotican_armadillo/description/meshes/torso_link.STL</uri>
            </mesh>
          </geometry>
        </visual>
        <visual name='torso_link_visual_arm_link'>
          <pose>0.19338 0 -0.25204 0 -0 0</pose>
          <geometry>
            <mesh>
              <scale>1 1 1</scale>
              <uri>/home/zeged/catkin_ws/src/robotican/robotican_armadillo/description/meshes/arm_link.STL</uri>
            </mesh>
          </geometry>
          <material>
            <script>
              <name>Gazebo/DarkGrey</name>
              <uri>__default__</uri>
            </script>
          </material>
          <material>
            <script>
              <name>Gazebo/DarkGrey</name>
              <uri>__default__</uri>
            </script>
          </material>
        </visual>
        <visual name='torso_link_visual_base_arm_link'>
          <pose>0.22638 0 -0.21629 0 -0 0</pose>
          <geometry>
            <mesh>
              <scale>1 1 1</scale>
              <uri>/home/zeged/catkin_ws/src/robotican/robotican_manipulator_h/meshes/base_arm_link.STL</uri>
            </mesh>
          </geometry>
          <material>
            <script>
              <name>Gazebo/DarkGrey</name>
              <uri>__default__</uri>
            </script>
          </material>
          <material>
            <script>
              <name>Gazebo/DarkGrey</name>
              <uri>__default__</uri>
            </script>
          </material>
          <material>
            <script>
              <name>Gazebo/DarkGrey</name>
              <uri>__default__</uri>
            </script>
          </material>
          <material>
            <script>
              <name>Gazebo/DarkGrey</name>
              <uri>__default__</uri>
            </script>
          </material>
          <material>
            <script>
              <name>Gazebo/Grey</name>
              <uri>__default__</uri>
            </script>
          </material>
        </visual>
        <visual name='torso_link_visual_head_link'>
          <pose>0.11288 0 0.26399 0 -0 0</pose>
          <geometry>
            <mesh>
              <scale>1 1 1</scale>
              <uri>/home/zeged/catkin_ws/src/robotican/robotican_armadillo/description/meshes/head_link.STL</uri>
            </mesh>
          </geometry>
        </visual>
        <visual name='torso_link_visual_rear_cam_link'>
          <pose>-0.09712 0 0.13354 0 -0 -3.14159</pose>
          <geometry>
            <mesh>
              <scale>1 1 1</scale>
              <uri>/home/zeged/catkin_ws/src/robotican/robotican_armadillo/description/meshes/rear_cam_link.STL</uri>
            </mesh>
          </geometry>
          <material>
            <script>
              <name>Gazebo/Black</name>
              <uri>__default__</uri>
            </script>
          </material>
        </visual>
        <velocity_decay>
          <linear>0</linear>
          <angular>0</angular>
        </velocity_decay>
        <velocity_decay>
          <linear>0</linear>
          <angular>0</angular>
        </velocity_decay>
        <velocity_decay>
          <linear>0</linear>
          <angular>0</angular>
        </velocity_decay>
        <velocity_decay>
          <linear>0</linear>
          <angular>0</angular>
        </velocity_decay>
        <velocity_decay>
          <linear>0</linear>
          <angular>0</angular>
        </velocity_decay>
        <gravity>1</gravity>
        <velocity_decay>
          <linear>0</linear>
          <angular>0</angular>
        </velocity_decay>
        <gravity>1</gravity>
        <velocity_decay>
          <linear>0</linear>
          <angular>0</angular>
        </velocity_decay>
        <self_collide>0</self_collide>
        <kinematic>0</kinematic>
      </link>
      <joint name='torso_joint' type='prismatic'>
        <child>torso_link</child>
        <parent>base_footprint</parent>
        <axis>
          <xyz>0 0 1</xyz>
          <limit>
            <lower>0</lower>
            <upper>0.32</upper>
            <effort>1.7652</effort>
            <velocity>0.1</velocity>
          </limit>
          <dynamics>
            <damping>1000</damping>
          </dynamics>
        </axis>
      </joint>
      <link name='rotation1_link'>
        <pose>0.08608 0 0.40252 0 -0 0</pose>
        <inertial>
          <pose>-3.5191e-10 0.0073117 0.037899 0 -0 0</pose>
          <mass>0.35317</mass>
          <inertia>
            <ixx>0.00055596</ixx>
            <ixy>9.2617e-12</ixy>
            <ixz>9.2232e-12</ixz>
            <iyy>0.00016945</iyy>
            <iyz>6.1918e-06</iyz>
            <izz>0.00055286</izz>
          </inertia>
        </inertial>
        <collision name='rotation1_link_collision'>
          <pose>0 0 0 0 -0 0</pose>
          <geometry>
            <mesh>
              <scale>1 1 1</scale>
              <uri>/home/zeged/catkin_ws/src/robotican/robotican_manipulator_h/meshes/rotation1_link.STL</uri>
            </mesh>
          </geometry>
          <surface>
            <contact>
              <ode/>
            </contact>
            <friction>
              <ode/>
            </friction>
            <bounce/>
          </surface>
          <max_contacts>10</max_contacts>
        </collision>
        <visual name='rotation1_link_visual'>
          <pose>0 0 0 0 -0 0</pose>
          <geometry>
            <mesh>
              <scale>1 1 1</scale>
              <uri>/home/zeged/catkin_ws/src/robotican/robotican_manipulator_h/meshes/rotation1_link.STL</uri>
            </mesh>
          </geometry>
          <material>
            <script>
              <name>Gazebo/DarkGrey</name>
              <uri>__default__</uri>
            </script>
          </material>
        </visual>
        <gravity>1</gravity>
        <velocity_decay>
          <linear>0</linear>
          <angular>0</angular>
        </velocity_decay>
        <self_collide>0</self_collide>
        <kinematic>0</kinematic>
      </link>
      <joint name='rotation1_joint' type='revolute'>
        <child>rotation1_link</child>
        <parent>torso_link</parent>
        <axis>
          <xyz>0 0 1</xyz>
          <limit>
            <lower>-1.57</lower>
            <upper>1.57</upper>
            <effort>44.7</effort>
            <velocity>2</velocity>
          </limit>
          <dynamics/>
        </axis>
      </joint>
      <link name='shoulder1_link'>
        <pose>0.08608 0 0.44152 0 -0 0</pose>
        <inertial>
          <pose>0.01628 0.00657 0.20044 0 -0 0</pose>
          <mass>0.52217</mass>
          <inertia>
            <ixx>0.0043595</ixx>
            <ixy>-3.1405e-06</ixy>
            <ixz>0.00053636</ixz>
            <iyy>0.0041046</iyy>
            <iyz>-5.2275e-05</iyz>
            <izz>0.00081871</izz>
          </inertia>
        </inertial>
        <collision name='shoulder1_link_collision'>
          <pose>0 0 0 0 -0 0</pose>
          <geometry>
            <mesh>
              <scale>1 1 1</scale>
              <uri>/home/zeged/catkin_ws/src/robotican/robotican_manipulator_h/meshes/shoulder1_link.STL</uri>
            </mesh>
          </geometry>
          <surface>
            <contact>
              <ode/>
            </contact>
            <friction>
              <ode/>
            </friction>
            <bounce/>
          </surface>
          <max_contacts>10</max_contacts>
        </collision>
        <visual name='shoulder1_link_visual'>
          <pose>0 0 0 0 -0 0</pose>
          <geometry>
            <mesh>
              <scale>1 1 1</scale>
              <uri>/home/zeged/catkin_ws/src/robotican/robotican_manipulator_h/meshes/shoulder1_link.STL</uri>
            </mesh>
          </geometry>
          <material>
            <script>
              <name>Gazebo/DarkGrey</name>
              <uri>__default__</uri>
            </script>
          </material>
        </visual>
        <gravity>1</gravity>
        <velocity_decay>
          <linear>0</linear>
          <angular>0</angular>
        </velocity_decay>
        <self_collide>0</self_collide>
        <kinematic>0</kinematic>
      </link>
      <joint name='shoulder1_joint' type='revolute'>
        <child>shoulder1_link</child>
        <parent>rotation1_link</parent>
        <axis>
          <xyz>0 1 0</xyz>
          <limit>
            <lower>-1.57</lower>
            <upper>1.95</upper>
            <effort>44.7</effort>
            <velocity>2</velocity>
          </limit>
          <dynamics/>
        </axis>
      </joint>
      <link name='shoulder2_link'>
        <pose>0.116078 0 0.70552 0 -0 0</pose>
        <inertial>
          <pose>0.068154 0.0063088 0.11032 0 -0 0</pose>
          <mass>0.47392</mass>
          <inertia>
            <ixx>0.00093237</ixx>
            <ixy>-1.0052e-05</ixy>
            <ixz>0.00048929</ixz>
            <iyy>0.0012859</iyy>
            <iyz>-1.3286e-05</iyz>
            <izz>0.00091329</izz>
          </inertia>
        </inertial>
        <collision name='shoulder2_link_collision'>
          <pose>0 0 0 0 -0 0</pose>
          <geometry>
            <mesh>
              <scale>1 1 1</scale>
              <uri>/home/zeged/catkin_ws/src/robotican/robotican_manipulator_h/meshes/shoulder2_link.STL</uri>
            </mesh>
          </geometry>
          <surface>
            <contact>
              <ode/>
            </contact>
            <friction>
              <ode/>
            </friction>
            <bounce/>
          </surface>
          <max_contacts>10</max_contacts>
        </collision>
        <visual name='shoulder2_link_visual'>
          <pose>0 0 0 0 -0 0</pose>
          <geometry>
            <mesh>
              <scale>1 1 1</scale>
              <uri>/home/zeged/catkin_ws/src/robotican/robotican_manipulator_h/meshes/shoulder2_link.STL</uri>
            </mesh>
          </geometry>
          <material>
            <script>
              <name>Gazebo/DarkGrey</name>
              <uri>__default__</uri>
            </script>
          </material>
        </visual>
        <gravity>1</gravity>
        <velocity_decay>
          <linear>0</linear>
          <angular>0</angular>
        </velocity_decay>
        <self_collide>0</self_collide>
        <kinematic>0</kinematic>
      </link>
      <joint name='shoulder2_joint' type='revolute'>
        <child>shoulder2_link</child>
        <parent>shoulder1_link</parent>
        <axis>
          <xyz>0 1 0</xyz>
          <limit>
            <lower>-1.48</lower>
            <upper>2.3522</upper>
            <effort>25.3</effort>
            <velocity>2</velocity>
          </limit>
          <dynamics/>
        </axis>
      </joint>
      <link name='rotation2_link'>
        <pose>0.254318 0.006 0.88619 -7.2737e-16 0.7854 -5.1433e-16</pose>
        <inertial>
          <pose>5.0638e-06 0.003816 0.026357 0 -0 0</pose>
          <mass>0.1635</mass>
          <inertia>
            <ixx>0.00014132</ixx>
            <ixy>-3.0872e-09</ixy>
            <ixz>1.6669e-08</ixz>
            <iyy>8.0775e-05</iyy>
            <iyz>3.4079e-06</iyz>
            <izz>0.00010687</izz>
          </inertia>
        </inertial>
        <collision name='rotation2_link_collision'>
          <pose>0 0 0 0 -0 0</pose>
          <geometry>
            <mesh>
              <scale>1 1 1</scale>
              <uri>/home/zeged/catkin_ws/src/robotican/robotican_manipulator_h/meshes/rotation2_link.STL</uri>
            </mesh>
          </geometry>
          <surface>
            <contact>
              <ode/>
            </contact>
            <friction>
              <ode/>
            </friction>
            <bounce/>
          </surface>
          <max_contacts>10</max_contacts>
        </collision>
        <visual name='rotation2_link_visual'>
          <pose>0 0 0 0 -0 0</pose>
          <geometry>
            <mesh>
              <scale>1 1 1</scale>
              <uri>/home/zeged/catkin_ws/src/robotican/robotican_manipulator_h/meshes/rotation2_link.STL</uri>
            </mesh>
          </geometry>
          <material>
            <script>
              <name>Gazebo/DarkGrey</name>
              <uri>__default__</uri>
            </script>
          </material>
        </visual>
        <gravity>1</gravity>
        <velocity_decay>
          <linear>0</linear>
          <angular>0</angular>
        </velocity_decay>
        <self_collide>0</self_collide>
        <kinematic>0</kinematic>
      </link>
      <joint name='rotation2_joint' type='revolute'>
        <child>rotation2_link</child>
        <parent>shoulder2_link</parent>
        <axis>
          <xyz>0.707108 0 0.707105</xyz>
          <limit>
            <lower>-1.57</lower>
            <upper>1.57</upper>
            <effort>25.3</effort>
            <velocity>2</velocity>
          </limit>
          <dynamics/>
        </axis>
      </joint>
      <link name='shoulder3_link'>
        <pose>0.277299 1.30104e-17 0.909171 2.05384e-15 0.7854 1.45228e-15</pose>
        <inertial>
          <pose>3.9874e-11 0.012748 0.069689 0 -0 0</pose>
          <mass>0.15954</mass>
          <inertia>
            <ixx>0.00018198</ixx>
            <ixy>2.1351e-13</ixy>
            <ixz>-2.3815e-13</ixz>
            <iyy>0.00015335</iyy>
            <iyz>-5.6341e-06</iyz>
            <izz>7.5641e-05</izz>
          </inertia>
        </inertial>
        <collision name='shoulder3_link_collision'>
          <pose>0 0 0 0 -0 0</pose>
          <geometry>
            <mesh>
              <scale>1 1 1</scale>
              <uri>/home/zeged/catkin_ws/src/robotican/robotican_manipulator_h/meshes/shoulder3_link.STL</uri>
            </mesh>
          </geometry>
          <surface>
            <contact>
              <ode/>
            </contact>
            <friction>
              <ode/>
            </friction>
            <bounce/>
          </surface>
          <max_contacts>10</max_contacts>
        </collision>
        <visual name='shoulder3_link_visual'>
          <pose>0 0 0 0 -0 0</pose>
          <geometry>
            <mesh>
              <scale>1 1 1</scale>
              <uri>/home/zeged/catkin_ws/src/robotican/robotican_manipulator_h/meshes/shoulder3_link.STL</uri>
            </mesh>
          </geometry>
          <material>
            <script>
              <name>Gazebo/DarkGrey</name>
              <uri>__default__</uri>
            </script>
          </material>
        </visual>
        <gravity>1</gravity>
        <velocity_decay>
          <linear>0</linear>
          <angular>0</angular>
        </velocity_decay>
        <self_collide>0</self_collide>
        <kinematic>0</kinematic>
      </link>
      <joint name='shoulder3_joint' type='revolute'>
        <child>shoulder3_link</child>
        <parent>rotation2_link</parent>
        <axis>
          <xyz>0 1 0</xyz>
          <limit>
            <lower>-1.57</lower>
            <upper>1.57</upper>
            <effort>5.1</effort>
            <velocity>2</velocity>
          </limit>
          <dynamics/>
        </axis>
      </joint>
      <link name='wrist_link'>
        <pose>0.360031 0.012 0.991902 4.52552e-16 0.7854 3.20001e-16</pose>
        <inertial>
          <pose>-0.0434152 -2.38222e-11 0.0645785 0 -0 0</pose>
          <mass>0.369822</mass>
          <inertia>
            <ixx>0.000492923</ixx>
            <ixy>6.29523e-12</ixy>
            <ixz>0.000171641</ixz>
            <iyy>0.000470395</iyy>
            <iyz>-3.15233e-12</iyz>
            <izz>0.000618014</izz>
          </inertia>
        </inertial>
        <collision name='wrist_link_collision'>
          <pose>0 0 0 0 -0 0</pose>
          <geometry>
            <mesh>
              <scale>1 1 1</scale>
              <uri>/home/zeged/catkin_ws/src/robotican/robotican_manipulator_h/meshes/wrist_link.STL</uri>
            </mesh>
          </geometry>
          <surface>
            <contact>
              <ode/>
            </contact>
            <friction>
              <ode/>
            </friction>
            <bounce/>
          </surface>
          <max_contacts>10</max_contacts>
        </collision>
        <collision name='wrist_link_collision_softkinetic_camera_link'>
          <pose>-0.05905 0 0.0203 3.14159 -1.57079 3.14159</pose>
          <geometry>
            <box>
              <size>0.04 0.11 0.04</size>
            </box>
          </geometry>
          <surface>
            <contact>
              <ode/>
            </contact>
            <friction>
              <ode/>
            </friction>
            <bounce/>
          </surface>
          <surface>
            <contact>
              <ode/>
            </contact>
            <friction>
              <ode/>
            </friction>
          </surface>
          <max_contacts>10</max_contacts>
        </collision>
        <visual name='wrist_link_visual'>
          <pose>0 0 0 0 -0 0</pose>
          <geometry>
            <mesh>
              <scale>1 1 1</scale>
              <uri>/home/zeged/catkin_ws/src/robotican/robotican_manipulator_h/meshes/wrist_link.STL</uri>
            </mesh>
          </geometry>
          <material>
            <script>
              <name>Gazebo/DarkGrey</name>
              <uri>__default__</uri>
            </script>
          </material>
        </visual>
        <visual name='wrist_link_visual_softkinetic_camera_link'>
          <pose>-0.05905 0 0.0203 9.79337e-12 4.89673e-12 1.5708</pose>
          <geometry>
            <mesh>
              <scale>1 1 1</scale>
              <uri>/home/zeged/catkin_ws/src/robotican/robotican_common/models/softkinetic_camera_ds325/softkinetic_camera_ds325.STL</uri>
            </mesh>
          </geometry>
          <material>
            <script>
              <name>Gazebo/Black</name>
              <uri>__default__</uri>
            </script>
          </material>
        </visual>
        <velocity_decay>
          <linear>0</linear>
          <angular>0</angular>
        </velocity_decay>
        <gravity>1</gravity>
        <velocity_decay>
          <linear>0</linear>
          <angular>0</angular>
        </velocity_decay>
        <self_collide>0</self_collide>
        <kinematic>0</kinematic>
      </link>
      <joint name='wrist_joint' type='revolute'>
        <child>wrist_link</child>
        <parent>shoulder3_link</parent>
        <axis>
          <xyz>0.707108 -0 0.707105</xyz>
          <limit>
            <lower>-3.14</lower>
            <upper>3.14</upper>
            <effort>5.1</effort>
            <velocity>2</velocity>
          </limit>
          <dynamics/>
        </axis>
      </joint>
      <link name='left_finger_link'>
        <pose>0.394149 0.033 1.02602 0.0257899 0.7854 1.45479e-15</pose>
        <inertial>
          <pose>-5.5511e-17 0.015773 0.034449 0 -0 0</pose>
          <mass>0.017607</mass>
          <inertia>
            <ixx>1.4795e-05</ixx>
            <ixy>-1.1493e-20</ixy>
            <ixz>2.9858e-20</ixz>
            <iyy>1.8029e-05</iyy>
            <iyz>8.8323e-07</iyz>
            <izz>5.2141e-06</izz>
          </inertia>
        </inertial>
        <collision name='left_finger_link_collision'>
          <pose>0 0 0 0 -0 0</pose>
          <geometry>
            <mesh>
              <scale>1 1 1</scale>
              <uri>/home/zeged/catkin_ws/src/robotican/robotican_manipulator_h/meshes/left_finger_link.STL</uri>
            </mesh>
          </geometry>
          <surface>
            <contact>
              <ode>
                <kp>1e+06</kp>
                <kd>100</kd>
                <max_vel>1</max_vel>
                <min_depth>0</min_depth>
              </ode>
            </contact>
            <friction>
              <ode>
                <mu>1</mu>
                <mu2>1</mu2>
                <fdir1>0 0 1</fdir1>
              </ode>
            </friction>
            <bounce/>
          </surface>
          <surface>
            <contact>
              <ode/>
            </contact>
            <friction>
              <ode/>
            </friction>
          </surface>
          <max_contacts>10</max_contacts>
        </collision>
        <visual name='left_finger_link_visual'>
          <pose>0 0 0 0 -0 0</pose>
          <geometry>
            <mesh>
              <scale>1 1 1</scale>
              <uri>/home/zeged/catkin_ws/src/robotican/robotican_manipulator_h/meshes/left_finger_link.STL</uri>
            </mesh>
          </geometry>
          <material>
            <script>
              <name>Gazebo/Grey</name>
              <uri>__default__</uri>
            </script>
          </material>
        </visual>
        <velocity_decay>
          <linear>0</linear>
          <angular>0</angular>
        </velocity_decay>
        <gravity>1</gravity>
        <velocity_decay>
          <linear>0</linear>
          <angular>0</angular>
        </velocity_decay>
        <self_collide>0</self_collide>
        <kinematic>0</kinematic>
      </link>
      <joint name='left_finger_joint' type='revolute'>
        <child>left_finger_link</child>
        <parent>wrist_link</parent>
        <axis>
          <xyz>0.707105 0 -0.707108</xyz>
          <limit>
            <lower>-1.57</lower>
            <upper>1.57</upper>
            <effort>3.1</effort>
            <velocity>2</velocity>
          </limit>
          <dynamics>
            <damping>100</damping>
          </dynamics>
        </axis>
        <physics>
          <provide_feedback>1</provide_feedback>
          <ode>
            <provide_feedback>1</provide_feedback>
            <implicit_spring_damper>1</implicit_spring_damper>
            <cfm_damping>1</cfm_damping>
            <limit>
              <cfm>0</cfm>
              <erp>0.2</erp>
            </limit>
          </ode>
        </physics>
      </joint>
      <link name='right_finger_link'>
        <pose>0.394149 -0.009 1.02602 -0.0257898 0.7854 1.74918e-15</pose>
        <inertial>
          <pose>2.2204e-16 -0.015773 0.034449 0 -0 0</pose>
          <mass>0.017607</mass>
          <inertia>
            <ixx>1.4795e-05</ixx>
            <ixy>-4.8655e-21</ixy>
            <ixz>6.7763e-21</ixz>
            <iyy>1.8029e-05</iyy>
            <iyz>-8.8323e-07</iyz>
            <izz>5.2141e-06</izz>
          </inertia>
        </inertial>
        <collision name='right_finger_link_collision'>
          <pose>0 0 0 0 -0 0</pose>
          <geometry>
            <mesh>
              <scale>1 1 1</scale>
              <uri>/home/zeged/catkin_ws/src/robotican/robotican_manipulator_h/meshes/right_finger_link.STL</uri>
            </mesh>
          </geometry>
          <surface>
            <contact>
              <ode>
                <kp>1e+06</kp>
                <kd>100</kd>
                <max_vel>1</max_vel>
                <min_depth>0</min_depth>
              </ode>
            </contact>
            <friction>
              <ode>
                <mu>1</mu>
                <mu2>1</mu2>
                <fdir1>0 0 1</fdir1>
              </ode>
            </friction>
            <bounce/>
          </surface>
          <surface>
            <contact>
              <ode>
                <kp>1e+06</kp>
                <kd>100</kd>
                <max_vel>1</max_vel>
                <min_depth>0</min_depth>
              </ode>
            </contact>
            <friction>
              <ode>
                <mu>1</mu>
                <mu2>1</mu2>
                <fdir1>0 0 1</fdir1>
              </ode>
            </friction>
          </surface>
          <surface>
            <contact>
              <ode/>
            </contact>
            <friction>
              <ode/>
            </friction>
          </surface>
          <max_contacts>10</max_contacts>
        </collision>
        <visual name='right_finger_link_visual'>
          <pose>0 0 0 0 -0 0</pose>
          <geometry>
            <mesh>
              <scale>1 1 1</scale>
              <uri>/home/zeged/catkin_ws/src/robotican/robotican_manipulator_h/meshes/right_finger_link.STL</uri>
            </mesh>
          </geometry>
          <material>
            <script>
              <name>Gazebo/Grey</name>
              <uri>__default__</uri>
            </script>
          </material>
        </visual>
        <velocity_decay>
          <linear>0</linear>
          <angular>0</angular>
        </velocity_decay>
        <velocity_decay>
          <linear>0</linear>
          <angular>0</angular>
        </velocity_decay>
        <gravity>1</gravity>
        <velocity_decay>
          <linear>0</linear>
          <angular>0</angular>
        </velocity_decay>
        <self_collide>0</self_collide>
        <kinematic>0</kinematic>
      </link>
      <joint name='right_finger_joint' type='revolute'>
        <child>right_finger_link</child>
        <parent>wrist_link</parent>
        <axis>
          <xyz>0.707105 0 -0.707108</xyz>
          <limit>
            <lower>-1.57</lower>
            <upper>1.57</upper>
            <effort>3.1</effort>
            <velocity>2</velocity>
          </limit>
          <dynamics>
            <damping>100</damping>
          </dynamics>
        </axis>
        <physics>
          <ode>
            <limit>
              <cfm>0</cfm>
              <erp>0.2</erp>
            </limit>
            <provide_feedback>1</provide_feedback>
            <implicit_spring_damper>1</implicit_spring_damper>
            <cfm_damping>1</cfm_damping>
          </ode>
          <provide_feedback>1</provide_feedback>
        </physics>
      </joint>
      <link name='head_pan_link'>
        <pose>-0.06242 0 0.9638 0 -0 0</pose>
        <inertial>
          <pose>-0.0035721 -0.00092628 0.033004 0 -0 0</pose>
          <mass>0.03653</mass>
          <inertia>
            <ixx>3.6365e-05</ixx>
            <ixy>-2.125e-07</ixy>
            <ixz>-4.0004e-07</ixz>
            <iyy>3.8545e-05</iyy>
            <iyz>-4.6643e-07</iyz>
            <izz>4.1521e-05</izz>
          </inertia>
        </inertial>
        <collision name='head_pan_link_collision'>
          <pose>0 0 0 0 -0 0</pose>
          <geometry>
            <mesh>
              <scale>1 1 1</scale>
              <uri>/home/zeged/catkin_ws/src/robotican/robotican_armadillo/description/meshes/head_pan_link.STL</uri>
            </mesh>
          </geometry>
          <max_contacts>10</max_contacts>
          <surface>
            <bounce/>
            <friction>
              <ode/>
            </friction>
            <contact>
              <ode/>
            </contact>
          </surface>
        </collision>
        <visual name='head_pan_link_visual'>
          <pose>0 0 0 0 -0 0</pose>
          <geometry>
            <mesh>
              <scale>1 1 1</scale>
              <uri>/home/zeged/catkin_ws/src/robotican/robotican_armadillo/description/meshes/head_pan_link.STL</uri>
            </mesh>
          </geometry>
        </visual>
        <velocity_decay>
          <linear>0</linear>
          <angular>0</angular>
        </velocity_decay>
        <self_collide>0</self_collide>
        <kinematic>0</kinematic>
        <gravity>1</gravity>
      </link>
      <joint name='head_pan_joint' type='revolute'>
        <child>head_pan_link</child>
        <parent>torso_link</parent>
        <axis>
          <xyz>0 0 1</xyz>
          <limit>
            <lower>-1.0472</lower>
            <upper>1.0472</upper>
            <effort>3.1</effort>
            <velocity>7.01622</velocity>
          </limit>
          <dynamics/>
        </axis>
      </joint>
      <link name='head_tilt_link'>
        <pose>-0.06242 0 1.0148 0 -0 0</pose>
        <inertial>
          <pose>0.0152305 0.000223572 0.0661366 0 -0 0</pose>
          <mass>1.84805</mass>
          <inertia>
            <ixx>0.0100546</ixx>
            <ixy>-2.83647e-05</ixy>
            <ixz>-1.96483e-05</ixz>
            <iyy>0.00223824</iyy>
            <iyz>1.0511e-06</iyz>
            <izz>0.0103498</izz>
          </inertia>
        </inertial>
        <collision name='head_tilt_link_collision'>
          <pose>0 0 0 0 -0 0</pose>
          <geometry>
            <mesh>
              <scale>1 1 1</scale>
              <uri>/home/zeged/catkin_ws/src/robotican/robotican_armadillo/description/meshes/head_tilt_link.STL</uri>
            </mesh>
          </geometry>
          <max_contacts>10</max_contacts>
          <surface>
            <bounce/>
            <friction>
              <ode/>
            </friction>
            <contact>
              <ode/>
            </contact>
          </surface>
        </collision>
        <collision name='head_tilt_link_collision_kinect2_link'>
          <pose>0.0518 0 0.07225 0 -0 0</pose>
          <geometry>
            <mesh>
              <scale>1 1 1</scale>
              <uri>/home/zeged/catkin_ws/src/robotican/robotican_armadillo/description/meshes/kinect2_link.STL</uri>
            </mesh>
          </geometry>
          <surface>
            <contact>
              <ode/>
            </contact>
            <friction>
              <ode/>
            </friction>
            <bounce/>
          </surface>
          <max_contacts>10</max_contacts>
        </collision>
        <visual name='head_tilt_link_visual'>
          <pose>0 0 0 0 -0 0</pose>
          <geometry>
            <mesh>
              <scale>1 1 1</scale>
              <uri>/home/zeged/catkin_ws/src/robotican/robotican_armadillo/description/meshes/head_tilt_link.STL</uri>
            </mesh>
          </geometry>
        </visual>
        <visual name='head_tilt_link_visual_kinect2_link'>
          <pose>0.0518 0 0.07225 0 -0 0</pose>
          <geometry>
            <mesh>
              <scale>1 1 1</scale>
              <uri>/home/zeged/catkin_ws/src/robotican/robotican_armadillo/description/meshes/kinect2_link.STL</uri>
            </mesh>
          </geometry>
          <material>
            <script>
              <name>Gazebo/Black</name>
              <uri>__default__</uri>
            </script>
          </material>
        </visual>
        <gravity>1</gravity>
        <velocity_decay>
          <linear>0</linear>
          <angular>0</angular>
        </velocity_decay>
        <self_collide>0</self_collide>
        <kinematic>0</kinematic>
      </link>
      <joint name='head_tilt_joint' type='revolute'>
        <child>head_tilt_link</child>
        <parent>head_pan_link</parent>
        <axis>
          <xyz>0 1 0</xyz>
          <limit>
            <lower>-0.523599</lower>
            <upper>1.0472</upper>
            <effort>3.1</effort>
            <velocity>7.01622</velocity>
          </limit>
          <dynamics/>
        </axis>
      </joint>
      <plugin name='gazebo_grasp_fix' filename='libgazebo_grasp_fix.so'>
        <arm>
          <arm_name>arm</arm_name>
          <palm_link>wrist_link</palm_link>
          <gripper_link>left_finger_link</gripper_link>
          <gripper_link>right_finger_link</gripper_link>
        </arm>
        <forces_angle_tolerance>100</forces_angle_tolerance>
        <update_rate>50</update_rate>
        <grip_count_threshold>4</grip_count_threshold>
        <max_grip_count>8</max_grip_count>
        <release_tolerance>0.005</release_tolerance>
        <disable_collisions_on_attach>false</disable_collisions_on_attach>
        <contact_topic>__default_topic__</contact_topic>
        <robotNamespace>/</robotNamespace>
      </plugin>
      <static>0</static>
      <plugin name='gazebo_ros_control' filename='libgazebo_ros_control.so'>
        <robotSimType>gazebo_ros_control/RoboticanRobotHWSim</robotSimType>
        <robotNamespace>/</robotNamespace>
      </plugin>
      <pose>0 0 0 0 -0 0</pose>
    </model>
  </world>
</sdf>
